<mujoco model="base">
  <compiler angle="radian" meshdir="meshes/"/>

  <option impratio="20" density="1.2" viscosity="2e-05" cone="elliptic"/>

  <size njmax="5000" nconmax="5000"/>

  <visual>
    <map znear="0.001"/>
  </visual>

  <asset>
    <texture type="skybox" colorspace="auto" builtin="gradient" rgb1="0.9 0.9 1" rgb2="0.2 0.3 0.4" width="256" height="1536"/>
    <texture type="2d" colorspace="sRGB" name="texplane" file="/home/achukrish/PegSlotSkill/robosuite/robosuite/models/assets/textures/light-gray-floor-tile.png"/>
    <texture type="2d" colorspace="linear" name="tex-light-gray-plaster" file="/home/achukrish/PegSlotSkill/robosuite/robosuite/models/assets/textures/light-gray-plaster.png"/>
    <material name="floorplane" texture="texplane" texuniform="true" texrepeat="2 2" specular="0" shininess="0" reflectance="0.01"/>
    <material name="walls_mat" texture="tex-light-gray-plaster" texuniform="true" texrepeat="3 3" specular="0.1" shininess="0.1"/>
    <material name="robot0_Face636_001" shininess="0.45" rgba="0.901961 0.921569 0.929412 1"/>
    <material name="robot0_Part__Feature017_001" shininess="0.45"/>
    <material name="robot0_Part__Feature018_001" shininess="0.45"/>
    <material name="robot0_Part__Feature019_001" shininess="0.45"/>
    <material name="robot0_Part__Feature022_001" shininess="0.45" rgba="0.901961 0.921569 0.929412 1"/>
    <material name="robot0_Part__Feature023_001" shininess="0.45" rgba="0.25098 0.25098 0.25098 1"/>
    <material name="robot0_Shell001_001" shininess="0.45" rgba="0.25098 0.25098 0.25098 1"/>
    <material name="robot0_Shell002_001" shininess="0.45" rgba="0.901961 0.921569 0.929412 1"/>
    <material name="robot0_Shell003_001" shininess="0.45" rgba="0.901961 0.921569 0.929412 1"/>
    <material name="robot0_Shell009_001" shininess="0.45" rgba="0.25098 0.25098 0.25098 1"/>
    <material name="robot0_Shell010_001" shininess="0.45" rgba="0.901961 0.921569 0.929412 1"/>
    <material name="robot0_Shell_001" shininess="0.45" rgba="0.25098 0.25098 0.25098 1"/>
    <material name="robot0_Part__Feature_001" shininess="0.45"/>
    <material name="robot0_Part__Feature024" shininess="0.45"/>
    <material name="robot0_Part__Feature001_010_001_002" shininess="0.45"/>
    <material name="robot0_Part__Feature002_007_001_002" shininess="0.45"/>
    <material name="robot0_Part__Feature003_004_001_002" shininess="0.45"/>
    <material name="robot0_Part__Feature_001_001_001_002" shininess="0.45" rgba="0.25098 0.25098 0.25098 1"/>
    <material name="robot0_Part__Feature001_001_003_001" shininess="0.45"/>
    <material name="robot0_Part__Feature002_001_003_001" shininess="0.45" rgba="0.25098 0.25098 0.25098 1"/>
    <material name="robot0_Part__Feature003_001_003_001" shininess="0.45"/>
    <material name="robot0_Part__Feature_002_003_001" shininess="0.45"/>
    <material name="robot0_Part__Feature_002_004_003" shininess="0.45"/>
    <material name="robot0_Shell001_001_001_003" shininess="0.45" rgba="0.25 0.25 0.25 1"/>
    <material name="robot0_Shell_001_001_003" shininess="0.45"/>
    <material name="robot0_Face064_002_001_002_001" shininess="0.45" rgba="1 0 0 1"/>
    <material name="robot0_Face065_002_001_002_001" shininess="0.45" rgba="0 1 0 1"/>
    <material name="robot0_Face374_002_001_002_001" shininess="0.45"/>
    <material name="robot0_Face539_002_001_002_001" shininess="0.45" rgba="0.25098 0.25098 0.25098 1"/>
    <material name="robot0_Part__Feature001_009_001_002_001" shininess="0.45" rgba="0.25098 0.25098 0.25098 1"/>
    <material name="robot0_Part__Feature002_006_001_002_001" shininess="0.45" rgba="0.25098 0.25098 0.25098 1"/>
    <material name="robot0_Shell002_002_001_002_001" shininess="0.45"/>
    <material name="robot0_Shell003_002_001_002_001" shininess="0.45"/>
    <material name="robot0_Shell004_001_001_002_001" shininess="0.45"/>
    <material name="robot0_Shell005_001_001_002_001" shininess="0.45"/>
    <material name="robot0_Shell006_003_002_001" shininess="0.45" rgba="0.901961 0.921569 0.929412 1"/>
    <material name="robot0_Shell007_002_002_001" shininess="0.45" rgba="0.25 0.25 0.25 1"/>
    <material name="robot0_Shell011_002_002_001" shininess="0.45"/>
    <material name="robot0_Shell012_002_002_001" shininess="0.45"/>
    <material name="robot0_Shell_003_001_002_001" shininess="0.45" rgba="0.25098 0.25098 0.25098 1"/>
    <material name="robot0_Union001_001_001_002_001" shininess="0.45" rgba="0.039216 0.541176 0.780392 1"/>
    <material name="robot0_Union_001_001_002_001" shininess="0.45" rgba="0.039216 0.541176 0.780392 1"/>
    <material name="robot0_Part__Mirroring001_004_002" shininess="0.45" rgba="0.25098 0.25098 0.25098 1"/>
    <material name="robot0_Part__Mirroring002_004_001" shininess="0.45" rgba="0.25098 0.25098 0.25098 1"/>
    <material name="robot0_Part__Mirroring003_004_001" shininess="0.45" rgba="0.25098 0.25098 0.25098 1"/>
    <material name="robot0_Part__Mirroring004_004_002" shininess="0.45"/>
    <material name="robot0_Part__Mirroring005_004_001" shininess="0.45" rgba="0.25098 0.25098 0.25098 1"/>
    <material name="robot0_Part__Mirroring006_004_001" shininess="0.45" rgba="0.25098 0.25098 0.25098 1"/>
    <material name="robot0_Part__Mirroring007_004_001" shininess="0.45" rgba="0.25098 0.25098 0.25098 1"/>
    <material name="robot0_Part__Mirroring_004_001" shininess="0.45" rgba="0.898039 0.917647 0.929412 1"/>
    <mesh name="robot0_link0" file="/home/achukrish/PegSlotSkill/robosuite/robosuite/models/assets/robots/panda/meshes/link0.stl"/>
    <mesh name="robot0_link1" file="/home/achukrish/PegSlotSkill/robosuite/robosuite/models/assets/robots/panda/meshes/link1.stl"/>
    <mesh name="robot0_link2" file="/home/achukrish/PegSlotSkill/robosuite/robosuite/models/assets/robots/panda/meshes/link2.stl"/>
    <mesh name="robot0_link3" file="/home/achukrish/PegSlotSkill/robosuite/robosuite/models/assets/robots/panda/meshes/link3.stl"/>
    <mesh name="robot0_link4" file="/home/achukrish/PegSlotSkill/robosuite/robosuite/models/assets/robots/panda/meshes/link4.stl"/>
    <mesh name="robot0_link5" file="/home/achukrish/PegSlotSkill/robosuite/robosuite/models/assets/robots/panda/meshes/link5.stl"/>
    <mesh name="robot0_link6" file="/home/achukrish/PegSlotSkill/robosuite/robosuite/models/assets/robots/panda/meshes/link6.stl"/>
    <mesh name="robot0_link7" file="/home/achukrish/PegSlotSkill/robosuite/robosuite/models/assets/robots/panda/meshes/link7.stl"/>
    <mesh name="robot0_link0_vis_0" file="/home/achukrish/PegSlotSkill/robosuite/robosuite/models/assets/robots/panda/obj_meshes/link0_vis/link0_vis_0.obj"/>
    <mesh name="robot0_link0_vis_1" file="/home/achukrish/PegSlotSkill/robosuite/robosuite/models/assets/robots/panda/obj_meshes/link0_vis/link0_vis_1.obj"/>
    <mesh name="robot0_link0_vis_2" file="/home/achukrish/PegSlotSkill/robosuite/robosuite/models/assets/robots/panda/obj_meshes/link0_vis/link0_vis_2.obj"/>
    <mesh name="robot0_link0_vis_3" file="/home/achukrish/PegSlotSkill/robosuite/robosuite/models/assets/robots/panda/obj_meshes/link0_vis/link0_vis_3.obj"/>
    <mesh name="robot0_link0_vis_4" file="/home/achukrish/PegSlotSkill/robosuite/robosuite/models/assets/robots/panda/obj_meshes/link0_vis/link0_vis_4.obj"/>
    <mesh name="robot0_link0_vis_5" file="/home/achukrish/PegSlotSkill/robosuite/robosuite/models/assets/robots/panda/obj_meshes/link0_vis/link0_vis_5.obj"/>
    <mesh name="robot0_link0_vis_6" file="/home/achukrish/PegSlotSkill/robosuite/robosuite/models/assets/robots/panda/obj_meshes/link0_vis/link0_vis_6.obj"/>
    <mesh name="robot0_link0_vis_7" file="/home/achukrish/PegSlotSkill/robosuite/robosuite/models/assets/robots/panda/obj_meshes/link0_vis/link0_vis_7.obj"/>
    <mesh name="robot0_link0_vis_8" file="/home/achukrish/PegSlotSkill/robosuite/robosuite/models/assets/robots/panda/obj_meshes/link0_vis/link0_vis_8.obj"/>
    <mesh name="robot0_link0_vis_9" file="/home/achukrish/PegSlotSkill/robosuite/robosuite/models/assets/robots/panda/obj_meshes/link0_vis/link0_vis_9.obj"/>
    <mesh name="robot0_link0_vis_10" file="/home/achukrish/PegSlotSkill/robosuite/robosuite/models/assets/robots/panda/obj_meshes/link0_vis/link0_vis_10.obj"/>
    <mesh name="robot0_link0_vis_11" file="/home/achukrish/PegSlotSkill/robosuite/robosuite/models/assets/robots/panda/obj_meshes/link0_vis/link0_vis_11.obj"/>
    <mesh name="robot0_link1_vis" file="/home/achukrish/PegSlotSkill/robosuite/robosuite/models/assets/robots/panda/obj_meshes/link1_vis/link1_vis.obj"/>
    <mesh name="robot0_link2_vis" file="/home/achukrish/PegSlotSkill/robosuite/robosuite/models/assets/robots/panda/obj_meshes/link2_vis/link2_vis.obj"/>
    <mesh name="robot0_link3_vis_0" file="/home/achukrish/PegSlotSkill/robosuite/robosuite/models/assets/robots/panda/obj_meshes/link3_vis/link3_vis_0.obj"/>
    <mesh name="robot0_link3_vis_1" file="/home/achukrish/PegSlotSkill/robosuite/robosuite/models/assets/robots/panda/obj_meshes/link3_vis/link3_vis_1.obj"/>
    <mesh name="robot0_link3_vis_2" file="/home/achukrish/PegSlotSkill/robosuite/robosuite/models/assets/robots/panda/obj_meshes/link3_vis/link3_vis_2.obj"/>
    <mesh name="robot0_link3_vis_3" file="/home/achukrish/PegSlotSkill/robosuite/robosuite/models/assets/robots/panda/obj_meshes/link3_vis/link3_vis_3.obj"/>
    <mesh name="robot0_link4_vis_0" file="/home/achukrish/PegSlotSkill/robosuite/robosuite/models/assets/robots/panda/obj_meshes/link4_vis/link4_vis_0.obj"/>
    <mesh name="robot0_link4_vis_1" file="/home/achukrish/PegSlotSkill/robosuite/robosuite/models/assets/robots/panda/obj_meshes/link4_vis/link4_vis_1.obj"/>
    <mesh name="robot0_link4_vis_2" file="/home/achukrish/PegSlotSkill/robosuite/robosuite/models/assets/robots/panda/obj_meshes/link4_vis/link4_vis_2.obj"/>
    <mesh name="robot0_link4_vis_3" file="/home/achukrish/PegSlotSkill/robosuite/robosuite/models/assets/robots/panda/obj_meshes/link4_vis/link4_vis_3.obj"/>
    <mesh name="robot0_link5_vis_0" file="/home/achukrish/PegSlotSkill/robosuite/robosuite/models/assets/robots/panda/obj_meshes/link5_vis/link5_vis_0.obj"/>
    <mesh name="robot0_link5_vis_1" file="/home/achukrish/PegSlotSkill/robosuite/robosuite/models/assets/robots/panda/obj_meshes/link5_vis/link5_vis_1.obj"/>
    <mesh name="robot0_link5_vis_2" file="/home/achukrish/PegSlotSkill/robosuite/robosuite/models/assets/robots/panda/obj_meshes/link5_vis/link5_vis_2.obj"/>
    <mesh name="robot0_link6_vis_0" file="/home/achukrish/PegSlotSkill/robosuite/robosuite/models/assets/robots/panda/obj_meshes/link6_vis/link6_vis_0.obj"/>
    <mesh name="robot0_link6_vis_1" file="/home/achukrish/PegSlotSkill/robosuite/robosuite/models/assets/robots/panda/obj_meshes/link6_vis/link6_vis_1.obj"/>
    <mesh name="robot0_link6_vis_2" file="/home/achukrish/PegSlotSkill/robosuite/robosuite/models/assets/robots/panda/obj_meshes/link6_vis/link6_vis_2.obj"/>
    <mesh name="robot0_link6_vis_3" file="/home/achukrish/PegSlotSkill/robosuite/robosuite/models/assets/robots/panda/obj_meshes/link6_vis/link6_vis_3.obj"/>
    <mesh name="robot0_link6_vis_4" file="/home/achukrish/PegSlotSkill/robosuite/robosuite/models/assets/robots/panda/obj_meshes/link6_vis/link6_vis_4.obj"/>
    <mesh name="robot0_link6_vis_5" file="/home/achukrish/PegSlotSkill/robosuite/robosuite/models/assets/robots/panda/obj_meshes/link6_vis/link6_vis_5.obj"/>
    <mesh name="robot0_link6_vis_6" file="/home/achukrish/PegSlotSkill/robosuite/robosuite/models/assets/robots/panda/obj_meshes/link6_vis/link6_vis_6.obj"/>
    <mesh name="robot0_link6_vis_7" file="/home/achukrish/PegSlotSkill/robosuite/robosuite/models/assets/robots/panda/obj_meshes/link6_vis/link6_vis_7.obj"/>
    <mesh name="robot0_link6_vis_8" file="/home/achukrish/PegSlotSkill/robosuite/robosuite/models/assets/robots/panda/obj_meshes/link6_vis/link6_vis_8.obj"/>
    <mesh name="robot0_link6_vis_9" file="/home/achukrish/PegSlotSkill/robosuite/robosuite/models/assets/robots/panda/obj_meshes/link6_vis/link6_vis_9.obj"/>
    <mesh name="robot0_link6_vis_10" file="/home/achukrish/PegSlotSkill/robosuite/robosuite/models/assets/robots/panda/obj_meshes/link6_vis/link6_vis_10.obj"/>
    <mesh name="robot0_link6_vis_11" file="/home/achukrish/PegSlotSkill/robosuite/robosuite/models/assets/robots/panda/obj_meshes/link6_vis/link6_vis_11.obj"/>
    <mesh name="robot0_link6_vis_12" file="/home/achukrish/PegSlotSkill/robosuite/robosuite/models/assets/robots/panda/obj_meshes/link6_vis/link6_vis_12.obj"/>
    <mesh name="robot0_link6_vis_13" file="/home/achukrish/PegSlotSkill/robosuite/robosuite/models/assets/robots/panda/obj_meshes/link6_vis/link6_vis_13.obj"/>
    <mesh name="robot0_link6_vis_14" file="/home/achukrish/PegSlotSkill/robosuite/robosuite/models/assets/robots/panda/obj_meshes/link6_vis/link6_vis_14.obj"/>
    <mesh name="robot0_link6_vis_15" file="/home/achukrish/PegSlotSkill/robosuite/robosuite/models/assets/robots/panda/obj_meshes/link6_vis/link6_vis_15.obj"/>
    <mesh name="robot0_link6_vis_16" file="/home/achukrish/PegSlotSkill/robosuite/robosuite/models/assets/robots/panda/obj_meshes/link6_vis/link6_vis_16.obj"/>
    <mesh name="robot0_link7_vis_0" file="/home/achukrish/PegSlotSkill/robosuite/robosuite/models/assets/robots/panda/obj_meshes/link7_vis/link7_vis_0.obj"/>
    <mesh name="robot0_link7_vis_1" file="/home/achukrish/PegSlotSkill/robosuite/robosuite/models/assets/robots/panda/obj_meshes/link7_vis/link7_vis_1.obj"/>
    <mesh name="robot0_link7_vis_2" file="/home/achukrish/PegSlotSkill/robosuite/robosuite/models/assets/robots/panda/obj_meshes/link7_vis/link7_vis_2.obj"/>
    <mesh name="robot0_link7_vis_3" file="/home/achukrish/PegSlotSkill/robosuite/robosuite/models/assets/robots/panda/obj_meshes/link7_vis/link7_vis_3.obj"/>
    <mesh name="robot0_link7_vis_4" file="/home/achukrish/PegSlotSkill/robosuite/robosuite/models/assets/robots/panda/obj_meshes/link7_vis/link7_vis_4.obj"/>
    <mesh name="robot0_link7_vis_5" file="/home/achukrish/PegSlotSkill/robosuite/robosuite/models/assets/robots/panda/obj_meshes/link7_vis/link7_vis_5.obj"/>
    <mesh name="robot0_link7_vis_6" file="/home/achukrish/PegSlotSkill/robosuite/robosuite/models/assets/robots/panda/obj_meshes/link7_vis/link7_vis_6.obj"/>
    <mesh name="robot0_link7_vis_7" file="/home/achukrish/PegSlotSkill/robosuite/robosuite/models/assets/robots/panda/obj_meshes/link7_vis/link7_vis_7.obj"/>
    <mesh name="gripper0_right_robotiq_arg2f_base_link" file="/home/achukrish/PegSlotSkill/robosuite/robosuite/models/assets/grippers/meshes/robotiq_85_gripper/robotiq_arg2f_base_link.stl"/>
    <mesh name="gripper0_right_robotiq_arg2f_85_outer_knuckle" file="/home/achukrish/PegSlotSkill/robosuite/robosuite/models/assets/grippers/meshes/robotiq_85_gripper/robotiq_arg2f_85_outer_knuckle.stl" scale="0.001 0.001 0.001"/>
    <mesh name="gripper0_right_robotiq_arg2f_85_outer_finger" file="/home/achukrish/PegSlotSkill/robosuite/robosuite/models/assets/grippers/meshes/robotiq_85_gripper/robotiq_arg2f_85_outer_finger.stl" scale="0.001 0.001 0.001"/>
    <mesh name="gripper0_right_robotiq_arg2f_85_inner_finger" file="/home/achukrish/PegSlotSkill/robosuite/robosuite/models/assets/grippers/meshes/robotiq_85_gripper/robotiq_arg2f_85_inner_finger.stl" scale="0.001 0.001 0.001"/>
    <mesh name="gripper0_right_robotiq_arg2f_85_inner_knuckle" file="/home/achukrish/PegSlotSkill/robosuite/robosuite/models/assets/grippers/meshes/robotiq_85_gripper/robotiq_arg2f_85_inner_knuckle.stl" scale="0.001 0.001 0.001"/>
    <mesh name="gripper0_right_robotiq_arg2f_85_outer_knuckle_vis" file="/home/achukrish/PegSlotSkill/robosuite/robosuite/models/assets/grippers/meshes/robotiq_85_gripper/robotiq_arg2f_85_outer_knuckle_vis.stl" scale="0.001 0.001 0.001"/>
    <mesh name="gripper0_right_robotiq_arg2f_85_outer_finger_vis" file="/home/achukrish/PegSlotSkill/robosuite/robosuite/models/assets/grippers/meshes/robotiq_85_gripper/robotiq_arg2f_85_outer_finger_vis.stl" scale="0.001 0.001 0.001"/>
    <mesh name="gripper0_right_robotiq_arg2f_85_inner_finger_vis" file="/home/achukrish/PegSlotSkill/robosuite/robosuite/models/assets/grippers/meshes/robotiq_85_gripper/robotiq_arg2f_85_inner_finger_vis.stl" scale="0.001 0.001 0.001"/>
    <mesh name="gripper0_right_robotiq_arg2f_85_inner_knuckle_vis" file="/home/achukrish/PegSlotSkill/robosuite/robosuite/models/assets/grippers/meshes/robotiq_85_gripper/robotiq_arg2f_85_inner_knuckle_vis.stl" scale="0.001 0.001 0.001"/>
    <mesh name="peg_mesh" file="/home/achukrish/PegSlotSkill/robosuite/robosuite/models/assets/objects/meshes/peg.stl" scale="0.001 0.001 0.001"/>
    <mesh name="slot_cuboid_visual" file="/home/achukrish/PegSlotSkill/robosuite/robosuite/models/assets/objects/meshes/cuboid.stl" scale="0.001 0.001 0.001"/>
    <mesh name="slot_cuboid_col_0" file="/home/achukrish/PegSlotSkill/robosuite/robosuite/models/assets/objects/meshes/cuboid_convex_0.stl" scale="0.001 0.001 0.001"/>
    <mesh name="slot_cuboid_col_1" file="/home/achukrish/PegSlotSkill/robosuite/robosuite/models/assets/objects/meshes/cuboid_convex_1.stl" scale="0.001 0.001 0.001"/>
    <mesh name="slot_cuboid_col_2" file="/home/achukrish/PegSlotSkill/robosuite/robosuite/models/assets/objects/meshes/cuboid_convex_2.stl" scale="0.001 0.001 0.001"/>
    <mesh name="slot_cuboid_col_3" file="/home/achukrish/PegSlotSkill/robosuite/robosuite/models/assets/objects/meshes/cuboid_convex_3.stl" scale="0.001 0.001 0.001"/>
    <mesh name="slot_cuboid_col_4" file="/home/achukrish/PegSlotSkill/robosuite/robosuite/models/assets/objects/meshes/cuboid_convex_4.stl" scale="0.001 0.001 0.001"/>
    <mesh name="slot_cuboid_col_5" file="/home/achukrish/PegSlotSkill/robosuite/robosuite/models/assets/objects/meshes/cuboid_convex_5.stl" scale="0.001 0.001 0.001"/>
    <mesh name="slot_cuboid_col_6" file="/home/achukrish/PegSlotSkill/robosuite/robosuite/models/assets/objects/meshes/cuboid_convex_6.stl" scale="0.001 0.001 0.001"/>
    <mesh name="slot_cuboid_col_7" file="/home/achukrish/PegSlotSkill/robosuite/robosuite/models/assets/objects/meshes/cuboid_convex_7.stl" scale="0.001 0.001 0.001"/>
    <mesh name="slot_cuboid_col_8" file="/home/achukrish/PegSlotSkill/robosuite/robosuite/models/assets/objects/meshes/cuboid_convex_8.stl" scale="0.001 0.001 0.001"/>
    <mesh name="slot_cuboid_col_9" file="/home/achukrish/PegSlotSkill/robosuite/robosuite/models/assets/objects/meshes/cuboid_convex_9.stl" scale="0.001 0.001 0.001"/>
    <mesh name="slot_cuboid_col_10" file="/home/achukrish/PegSlotSkill/robosuite/robosuite/models/assets/objects/meshes/cuboid_convex_10.stl" scale="0.001 0.001 0.001"/>
    <mesh name="slot_cuboid_col_11" file="/home/achukrish/PegSlotSkill/robosuite/robosuite/models/assets/objects/meshes/cuboid_convex_11.stl" scale="0.001 0.001 0.001"/>
    <mesh name="slot_cuboid_mesh" file="/home/achukrish/PegSlotSkill/robosuite/robosuite/models/assets/objects/meshes/cuboid.stl" scale="0.001 0.001 0.001"/>
  </asset>

  <worldbody>
    <geom name="floor" size="3 3 0.125" type="plane" group="1" material="floorplane"/>
    <geom name="wall_leftcorner_visual" size="1.06 1.5 0.01" pos="-1.25 2.25 1.5" quat="0.653281 0.653281 0.270598 0.270598" type="box" contype="0" conaffinity="0" group="1" material="walls_mat"/>
    <geom name="wall_rightcorner_visual" size="1.06 1.5 0.01" pos="-1.25 -2.25 1.5" quat="0.653281 0.653281 -0.270598 -0.270598" type="box" contype="0" conaffinity="0" group="1" material="walls_mat"/>
    <geom name="wall_left_visual" size="1.75 1.5 0.01" pos="1.25 3 1.5" quat="0.707107 0.707107 0 0" type="box" contype="0" conaffinity="0" group="1" material="walls_mat"/>
    <geom name="wall_right_visual" size="1.75 1.5 0.01" pos="1.25 -3 1.5" quat="0.707107 -0.707107 0 0" type="box" contype="0" conaffinity="0" group="1" material="walls_mat"/>
    <geom name="wall_rear_visual" size="1.5 1.5 0.01" pos="-2 0 1.5" quat="0.5 0.5 0.5 0.5" type="box" contype="0" conaffinity="0" group="1" material="walls_mat"/>
    <geom name="wall_front_visual" size="3 1.5 0.01" pos="3 0 1.5" quat="0.5 0.5 -0.5 -0.5" type="box" contype="0" conaffinity="0" group="1" material="walls_mat"/>
    <camera name="frontview" pos="1.6 0 0.45" quat="0.560842 0.430646 0.430646 0.560842"/>
    <camera name="birdview" pos="-0.2 0 3" quat="0.707107 0 0 0.707107"/>
    <camera name="agentview" pos="0.5 0 0.75" quat="0.653098 0.271041 0.271041 0.653098"/>
    <camera name="sideview" pos="-0.0565177 1.07612 0.487957" quat="0.00990507 0.00687796 0.591223 0.806418"/>
    <light pos="1 1 1.5" dir="-0.19245 -0.19245 -0.96225" type="directional" castshadow="false"/>
    <body name="left_eef_target" pos="0 0 -1" mocap="true">
      <geom name="left_eef_target_box" size="0.05 0.05 0.05" type="box" contype="0" conaffinity="0" group="2" rgba="0.898 0.42 0.435 0.5"/>
      <geom name="left_eef_target_sphere" size="0.01" contype="0" conaffinity="0" group="2" rgba="0.898 0.42 0.435 0.8"/>
    </body>
    <body name="right_eef_target" pos="0 0 -1" mocap="true">
      <geom name="right_eef_target_box" size="0.05 0.05 0.05" type="box" contype="0" conaffinity="0" group="2" rgba="0.208 0.314 0.439 0.5"/>
      <geom name="right_eef_target_sphere" size="0.01" contype="0" conaffinity="0" group="2" rgba="0.208 0.314 0.439 0.8"/>
    </body>
    <body name="robot0_base">
      <body name="mobilebase0_support">
        <inertial pos="-0.0508888 0.000109183 -0.0455794" quat="0.706855 0.707166 0.0123661 -0.0109307" mass="6.45117" diaginertia="0.0149302 0.0127972 0.00640923"/>
        <site name="mobilebase0_center" pos="0 0 0" size="0.01" group="1" rgba="0 0 0 0"/>
        <body name="manipulator_mount">
          <camera name="robot0_robotview" pos="1 0 0.4" quat="0.653098 0.271041 0.271041 0.653098"/>
          <body name="robot0_link0">
            <inertial pos="0 0 0.05" mass="4" diaginertia="0.4 0.4 0.4"/>
            <geom name="robot0_g0_vis" type="mesh" contype="0" conaffinity="0" group="1" material="robot0_Shell010_001" mesh="robot0_link0_vis_0"/>
            <geom name="robot0_g1_vis" type="mesh" contype="0" conaffinity="0" group="1" material="robot0_Shell009_001" mesh="robot0_link0_vis_1"/>
            <geom name="robot0_g2_vis" type="mesh" contype="0" conaffinity="0" group="1" material="robot0_Shell003_001" mesh="robot0_link0_vis_2"/>
            <geom name="robot0_g3_vis" type="mesh" contype="0" conaffinity="0" group="1" material="robot0_Shell_001" mesh="robot0_link0_vis_3"/>
            <geom name="robot0_g4_vis" type="mesh" contype="0" conaffinity="0" group="1" material="robot0_Shell002_001" mesh="robot0_link0_vis_4"/>
            <geom name="robot0_g5_vis" type="mesh" contype="0" conaffinity="0" group="1" material="robot0_Shell001_001" mesh="robot0_link0_vis_5"/>
            <geom name="robot0_g6_vis" type="mesh" contype="0" conaffinity="0" group="1" material="robot0_Face636_001" mesh="robot0_link0_vis_6"/>
            <geom name="robot0_g7_vis" type="mesh" contype="0" conaffinity="0" group="1" material="robot0_Part__Feature018_001" mesh="robot0_link0_vis_7"/>
            <geom name="robot0_g8_vis" type="mesh" contype="0" conaffinity="0" group="1" material="robot0_Part__Feature019_001" mesh="robot0_link0_vis_8"/>
            <geom name="robot0_g9_vis" type="mesh" contype="0" conaffinity="0" group="1" material="robot0_Part__Feature023_001" mesh="robot0_link0_vis_9"/>
            <geom name="robot0_g10_vis" type="mesh" contype="0" conaffinity="0" group="1" material="robot0_Part__Feature022_001" mesh="robot0_link0_vis_10"/>
            <geom name="robot0_g11_vis" type="mesh" contype="0" conaffinity="0" group="1" material="robot0_Part__Feature017_001" mesh="robot0_link0_vis_11"/>
            <geom name="robot0_link0_collision" type="mesh" rgba="0 0.5 0 1" mesh="robot0_link0"/>
            <site name="robot0_right_center" pos="0 0 0" size="0.01" group="2" rgba="1 0.3 0.3 1"/>
            <body name="robot0_link1" pos="0 0 0.333">
              <inertial pos="0 0 -0.07" mass="3" diaginertia="0.3 0.3 0.3"/>
              <joint name="robot0_joint1" pos="0 0 0" axis="0 0 1" limited="true" range="-2.8973 2.8973" armature="5" damping="0.1" frictionloss="0.1"/>
              <geom name="robot0_g12_vis" type="mesh" contype="0" conaffinity="0" group="1" material="robot0_Part__Feature_001" mesh="robot0_link1_vis"/>
              <geom name="robot0_link1_collision" type="mesh" rgba="0 0.5 0 1" mesh="robot0_link1"/>
              <body name="robot0_link2" quat="0.707107 -0.707107 0 0">
                <inertial pos="0 -0.1 0" mass="3" diaginertia="0.3 0.3 0.3"/>
                <joint name="robot0_joint2" pos="0 0 0" axis="0 0 1" limited="true" range="-1.7628 1.7628" armature="2.5" damping="0.1" frictionloss="0.1"/>
                <geom name="robot0_g13_vis" type="mesh" contype="0" conaffinity="0" group="1" material="robot0_Part__Feature024" mesh="robot0_link2_vis"/>
                <geom name="robot0_link2_collision" type="mesh" rgba="0 0.5 0 1" mesh="robot0_link2"/>
                <body name="robot0_link3" pos="0 -0.316 0" quat="0.707107 0.707107 0 0">
                  <inertial pos="0.04 0 -0.05" mass="2" diaginertia="0.2 0.2 0.2"/>
                  <joint name="robot0_joint3" pos="0 0 0" axis="0 0 1" limited="true" range="-2.8973 2.8973" armature="1.66667" damping="0.1" frictionloss="0.1"/>
                  <geom name="robot0_g14_vis" type="mesh" contype="0" conaffinity="0" group="1" material="robot0_Part__Feature003_004_001_002" mesh="robot0_link3_vis_0"/>
                  <geom name="robot0_g15_vis" type="mesh" contype="0" conaffinity="0" group="1" material="robot0_Part__Feature002_007_001_002" mesh="robot0_link3_vis_1"/>
                  <geom name="robot0_g16_vis" type="mesh" contype="0" conaffinity="0" group="1" material="robot0_Part__Feature001_010_001_002" mesh="robot0_link3_vis_2"/>
                  <geom name="robot0_g17_vis" type="mesh" contype="0" conaffinity="0" group="1" material="robot0_Part__Feature_001_001_001_002" mesh="robot0_link3_vis_3"/>
                  <geom name="robot0_link3_collision" type="mesh" rgba="0 0.5 0 1" mesh="robot0_link3"/>
                  <body name="robot0_link4" pos="0.0825 0 0" quat="0.707107 0.707107 0 0">
                    <inertial pos="-0.04 0.05 0" mass="2" diaginertia="0.2 0.2 0.2"/>
                    <joint name="robot0_joint4" pos="0 0 0" axis="0 0 1" limited="true" range="-3.0718 -0.0698" armature="1.25" damping="0.1" frictionloss="0.1"/>
                    <geom name="robot0_g18_vis" type="mesh" contype="0" conaffinity="0" group="1" material="robot0_Part__Feature001_001_003_001" mesh="robot0_link4_vis_0"/>
                    <geom name="robot0_g19_vis" type="mesh" contype="0" conaffinity="0" group="1" material="robot0_Part__Feature003_001_003_001" mesh="robot0_link4_vis_1"/>
                    <geom name="robot0_g20_vis" type="mesh" contype="0" conaffinity="0" group="1" material="robot0_Part__Feature002_001_003_001" mesh="robot0_link4_vis_2"/>
                    <geom name="robot0_g21_vis" type="mesh" contype="0" conaffinity="0" group="1" material="robot0_Part__Feature_002_003_001" mesh="robot0_link4_vis_3"/>
                    <geom name="robot0_link4_collision" type="mesh" rgba="0 0.5 0 1" mesh="robot0_link4"/>
                    <body name="robot0_link5" pos="-0.0825 0.384 0" quat="0.707107 -0.707107 0 0">
                      <inertial pos="0 0 -0.15" mass="2" diaginertia="0.2 0.2 0.2"/>
                      <joint name="robot0_joint5" pos="0 0 0" axis="0 0 1" limited="true" range="-2.8973 2.8973" armature="1" damping="0.1" frictionloss="0.1"/>
                      <geom name="robot0_g22_vis" type="mesh" contype="0" conaffinity="0" group="1" material="robot0_Shell001_001_001_003" mesh="robot0_link5_vis_0"/>
                      <geom name="robot0_g23_vis" type="mesh" contype="0" conaffinity="0" group="1" material="robot0_Shell_001_001_003" mesh="robot0_link5_vis_1"/>
                      <geom name="robot0_g24_vis" type="mesh" contype="0" conaffinity="0" group="1" material="robot0_Part__Feature_002_004_003" mesh="robot0_link5_vis_2"/>
                      <geom name="robot0_link5_collision" type="mesh" rgba="0 0.5 0 1" mesh="robot0_link5"/>
                      <body name="robot0_link6" quat="0.707107 0.707107 0 0">
                        <inertial pos="0.06 0 0" mass="1.5" diaginertia="0.1 0.1 0.1"/>
                        <joint name="robot0_joint6" pos="0 0 0" axis="0 0 1" limited="true" range="-0.0175 3.7525" armature="0.833333" damping="0.01" frictionloss="0.1"/>
                        <geom name="robot0_g25_vis" type="mesh" contype="0" conaffinity="0" group="1" material="robot0_Shell006_003_002_001" mesh="robot0_link6_vis_0"/>
                        <geom name="robot0_g26_vis" type="mesh" contype="0" conaffinity="0" group="1" material="robot0_Shell011_002_002_001" mesh="robot0_link6_vis_1"/>
                        <geom name="robot0_g27_vis" type="mesh" contype="0" conaffinity="0" group="1" material="robot0_Shell007_002_002_001" mesh="robot0_link6_vis_2"/>
                        <geom name="robot0_g28_vis" type="mesh" contype="0" conaffinity="0" group="1" material="robot0_Shell005_001_001_002_001" mesh="robot0_link6_vis_3"/>
                        <geom name="robot0_g29_vis" type="mesh" contype="0" conaffinity="0" group="1" material="robot0_Shell004_001_001_002_001" mesh="robot0_link6_vis_4"/>
                        <geom name="robot0_g30_vis" type="mesh" contype="0" conaffinity="0" group="1" material="robot0_Shell003_002_001_002_001" mesh="robot0_link6_vis_5"/>
                        <geom name="robot0_g31_vis" type="mesh" contype="0" conaffinity="0" group="1" material="robot0_Shell002_002_001_002_001" mesh="robot0_link6_vis_6"/>
                        <geom name="robot0_g32_vis" type="mesh" contype="0" conaffinity="0" group="1" material="robot0_Union001_001_001_002_001" mesh="robot0_link6_vis_7"/>
                        <geom name="robot0_g33_vis" type="mesh" contype="0" conaffinity="0" group="1" material="robot0_Union_001_001_002_001" mesh="robot0_link6_vis_8"/>
                        <geom name="robot0_g34_vis" type="mesh" contype="0" conaffinity="0" group="1" material="robot0_Face539_002_001_002_001" mesh="robot0_link6_vis_9"/>
                        <geom name="robot0_g35_vis" type="mesh" contype="0" conaffinity="0" group="1" material="robot0_Shell_003_001_002_001" mesh="robot0_link6_vis_10"/>
                        <geom name="robot0_g36_vis" type="mesh" contype="0" conaffinity="0" group="1" material="robot0_Face374_002_001_002_001" mesh="robot0_link6_vis_11"/>
                        <geom name="robot0_g37_vis" type="mesh" contype="0" conaffinity="0" group="1" material="robot0_Face065_002_001_002_001" mesh="robot0_link6_vis_12"/>
                        <geom name="robot0_g38_vis" type="mesh" contype="0" conaffinity="0" group="1" material="robot0_Face064_002_001_002_001" mesh="robot0_link6_vis_13"/>
                        <geom name="robot0_g39_vis" type="mesh" contype="0" conaffinity="0" group="1" material="robot0_Part__Feature002_006_001_002_001" mesh="robot0_link6_vis_14"/>
                        <geom name="robot0_g40_vis" type="mesh" contype="0" conaffinity="0" group="1" material="robot0_Part__Feature001_009_001_002_001" mesh="robot0_link6_vis_15"/>
                        <geom name="robot0_g41_vis" type="mesh" contype="0" conaffinity="0" group="1" material="robot0_Shell012_002_002_001" mesh="robot0_link6_vis_16"/>
                        <geom name="robot0_link6_collision" type="mesh" rgba="0 0.5 0 1" mesh="robot0_link6"/>
                        <body name="robot0_link7" pos="0.088 0 0" quat="0.707107 0.707107 0 0">
                          <inertial pos="0 0 0.08" mass="0.5" diaginertia="0.05 0.05 0.05"/>
                          <joint name="robot0_joint7" pos="0 0 0" axis="0 0 1" limited="true" range="-2.8973 2.8973" armature="0.714286" damping="0.01" frictionloss="0.1"/>
                          <geom name="robot0_g42_vis" type="mesh" contype="0" conaffinity="0" group="1" material="robot0_Part__Mirroring004_004_002" mesh="robot0_link7_vis_0"/>
                          <geom name="robot0_g43_vis" type="mesh" contype="0" conaffinity="0" group="1" material="robot0_Part__Mirroring001_004_002" mesh="robot0_link7_vis_1"/>
                          <geom name="robot0_g44_vis" type="mesh" contype="0" conaffinity="0" group="1" material="robot0_Part__Mirroring007_004_001" mesh="robot0_link7_vis_2"/>
                          <geom name="robot0_g45_vis" type="mesh" contype="0" conaffinity="0" group="1" material="robot0_Part__Mirroring006_004_001" mesh="robot0_link7_vis_3"/>
                          <geom name="robot0_g46_vis" type="mesh" contype="0" conaffinity="0" group="1" material="robot0_Part__Mirroring005_004_001" mesh="robot0_link7_vis_4"/>
                          <geom name="robot0_g47_vis" type="mesh" contype="0" conaffinity="0" group="1" material="robot0_Part__Mirroring003_004_001" mesh="robot0_link7_vis_5"/>
                          <geom name="robot0_g48_vis" type="mesh" contype="0" conaffinity="0" group="1" material="robot0_Part__Mirroring002_004_001" mesh="robot0_link7_vis_6"/>
                          <geom name="robot0_g49_vis" type="mesh" contype="0" conaffinity="0" group="1" material="robot0_Part__Mirroring_004_001" mesh="robot0_link7_vis_7"/>
                          <geom name="robot0_link7_collision" type="mesh" rgba="0 0.5 0 1" mesh="robot0_link7"/>
                          <body name="robot0_right_hand" pos="0 0 0.1065" quat="0.923785 0 0 -0.382911">
                            <inertial pos="0 0 0" mass="0.5" diaginertia="0.05 0.05 0.05"/>
                            <camera name="robot0_eye_in_hand" pos="0.05 0 0" quat="0 0.707107 0.707107 0" fovy="75"/>
                            <body name="gripper0_right_robotiq_85_adapter_link">
                              <inertial pos="0 0 0" mass="0.01" diaginertia="0.001 0.001 0.001"/>
                              <geom name="gripper0_right_hand_visual" type="mesh" contype="0" conaffinity="0" group="1" rgba="0.1 0.1 0.1 1" mesh="gripper0_right_robotiq_arg2f_base_link"/>
                              <geom name="gripper0_right_hand_collision" type="mesh" rgba="0 0 0.5 1" mesh="gripper0_right_robotiq_arg2f_base_link"/>
                              <site name="gripper0_right_ft_frame" pos="0 0 0" size="0.01" group="1" rgba="1 0 0 1"/>
                              <body name="gripper0_right_eef" pos="0 0 0.145" quat="0.707107 0 0 -0.707107">
                                <site name="gripper0_right_grip_site" pos="0 0 0" size="0.01" group="1" rgba="0.596324 0.403676 0 0.5"/>
                                <site name="gripper0_right_ee_x" pos="0.1 0 0" quat="0.707105 0 0.707108 0" size="0.005 0.1" group="1" type="cylinder" rgba="1 0 0 0"/>
                                <site name="gripper0_right_ee_y" pos="0 0.1 0" quat="0.707105 0.707108 0 0" size="0.005 0.1" group="1" type="cylinder" rgba="0 1 0 0"/>
                                <site name="gripper0_right_ee_z" pos="0 0 0.1" size="0.005 0.1" group="1" type="cylinder" rgba="0 0 1 0"/>
                                <site name="gripper0_right_grip_site_cylinder" pos="0 0 0" size="0.005 10" group="1" type="cylinder" rgba="0 1 0 0.3"/>
                              </body>
                              <body name="gripper0_right_left_outer_knuckle" pos="0 -0.0306011 0.054904" quat="0 0 0 1">
                                <inertial pos="0.000163875 0.0554825 -0.0100755" quat="0.920541 0.390623 -0.00362953 0.00231744" mass="0.0311462" diaginertia="5.11372e-05 4.89464e-05 4.95906e-06"/>
                                <joint name="gripper0_right_finger_joint" pos="0 0 0" axis="1 0 0" limited="true" range="0 0.8"/>
                                <geom name="gripper0_right_left_outer_knuckle_visual" type="mesh" contype="0" conaffinity="0" group="1" rgba="0.792157 0.819608 0.933333 1" mesh="gripper0_right_robotiq_arg2f_85_outer_knuckle_vis"/>
                                <geom name="gripper0_right_left_outer_knuckle_collision" type="mesh" solref="0.01 0.25" rgba="0 0 0.5 1" mesh="gripper0_right_robotiq_arg2f_85_outer_knuckle"/>
                                <geom name="gripper0_right_left_outer_finger_visual" pos="0 0.0315 -0.0041" quat="1 0 0 0" type="mesh" contype="0" conaffinity="0" group="1" rgba="0.1 0.1 0.1 1" mesh="gripper0_right_robotiq_arg2f_85_outer_finger_vis"/>
                                <geom name="gripper0_right_left_outer_finger_collision" pos="0 0.0315 -0.0041" quat="1 0 0 0" type="mesh" solref="0.01 0.25" rgba="0 0 0.5 1" mesh="gripper0_right_robotiq_arg2f_85_outer_finger"/>
                                <body name="gripper0_right_left_inner_finger" pos="0 0.0376 0.043">
                                  <inertial pos="0.000199506 0.0032692 0.00175282" quat="0.933621 0.35825 -0.00273441 0.00104851" mass="0.0156391" diaginertia="1.57977e-05 1.51089e-05 1.4647e-06"/>
                                  <joint name="gripper0_right_left_inner_finger_joint" pos="0 0 0" axis="1 0 0" limited="true" range="-0.8757 0.8757"/>
                                  <geom name="gripper0_right_left_inner_finger_visual" type="mesh" contype="0" conaffinity="0" group="1" rgba="0.1 0.1 0.1 1" mesh="gripper0_right_robotiq_arg2f_85_inner_finger_vis"/>
                                  <geom name="gripper0_right_left_inner_finger_collision" type="mesh" solref="0.01 0.25" rgba="0 0 0.5 1" mesh="gripper0_right_robotiq_arg2f_85_inner_finger"/>
                                  <geom name="gripper0_right_left_fingertip_visual" size="0.011 0.003175 0.01875" pos="0 -0.0220203 0.03242" type="box" contype="0" conaffinity="0" group="1" rgba="0.9 0.9 0.9 1"/>
                                  <geom name="gripper0_right_left_fingertip_collision" size="0.011 0.003175 0.01875" pos="0 -0.0220203 0.03242" type="box" solref="0.01 0.25" rgba="0 0 0.5 1"/>
                                  <geom name="gripper0_right_left_fingerpad_collision" size="0.01 0.001 0.01675" pos="0 -0.0245203 0.03242" type="box" rgba="0 0 0.5 1"/>
                                </body>
                              </body>
                              <body name="gripper0_right_left_inner_knuckle" pos="0 -0.0127 0.06142" quat="0 0 0 1">
                                <inertial pos="0.000123012 0.0507851 0.00103969" quat="0.497203 0.502496 -0.507943 0.492221" mass="0.0271177" diaginertia="2.83809e-05 2.61936e-05 2.81319e-06"/>
                                <joint name="gripper0_right_left_inner_knuckle_joint" pos="0 0 0" axis="1 0 0" limited="true" range="0 0.8757"/>
                                <geom name="gripper0_right_left_inner_knuckle_visual" type="mesh" contype="0" conaffinity="0" group="1" rgba="0.1 0.1 0.1 1" mesh="gripper0_right_robotiq_arg2f_85_inner_knuckle_vis"/>
                                <geom name="gripper0_right_left_inner_knuckle_collision" type="mesh" rgba="0 0 0.5 1" mesh="gripper0_right_robotiq_arg2f_85_inner_knuckle"/>
                              </body>
                              <body name="gripper0_right_right_outer_knuckle" pos="0 0.0306011 0.054904">
                                <inertial pos="0.000163875 0.0554825 -0.0100755" quat="0.920541 0.390623 -0.00362953 0.00231744" mass="0.0311462" diaginertia="5.11372e-05 4.89464e-05 4.95906e-06"/>
                                <joint name="gripper0_right_right_outer_knuckle_joint" pos="0 0 0" axis="1 0 0" limited="true" range="0 0.8"/>
                                <geom name="gripper0_right_right_outer_knuckle_visual" type="mesh" contype="0" conaffinity="0" group="1" rgba="0.792157 0.819608 0.933333 1" mesh="gripper0_right_robotiq_arg2f_85_outer_knuckle_vis"/>
                                <geom name="gripper0_right_right_outer_knuckle_collision" type="mesh" solref="0.01 0.25" rgba="0 0 0.5 1" mesh="gripper0_right_robotiq_arg2f_85_outer_knuckle"/>
                                <geom name="gripper0_right_right_outer_finger_visual" pos="0 0.0315 -0.0041" quat="1 0 0 0" type="mesh" contype="0" conaffinity="0" group="1" rgba="0.1 0.1 0.1 1" mesh="gripper0_right_robotiq_arg2f_85_outer_finger_vis"/>
                                <geom name="gripper0_right_right_outer_finger_collision" pos="0 0.0315 -0.0041" quat="1 0 0 0" type="mesh" solref="0.01 0.25" rgba="0 0 0.5 1" mesh="gripper0_right_robotiq_arg2f_85_outer_finger"/>
                                <body name="gripper0_right_right_inner_finger" pos="0 0.0376 0.043">
                                  <inertial pos="0.000199506 0.0032692 0.00175282" quat="0.933621 0.35825 -0.00273441 0.00104851" mass="0.0156391" diaginertia="1.57977e-05 1.51089e-05 1.4647e-06"/>
                                  <joint name="gripper0_right_right_inner_finger_joint" pos="0 0 0" axis="1 0 0" limited="true" range="-0.8757 0.8757"/>
                                  <geom name="gripper0_right_right_inner_finger_visual" type="mesh" contype="0" conaffinity="0" group="1" rgba="0.1 0.1 0.1 1" mesh="gripper0_right_robotiq_arg2f_85_inner_finger_vis"/>
                                  <geom name="gripper0_right_right_inner_finger_collision" type="mesh" solref="0.01 0.25" rgba="0 0 0.5 1" mesh="gripper0_right_robotiq_arg2f_85_inner_finger"/>
                                  <geom name="gripper0_right_right_fingertip_visual" size="0.011 0.003175 0.01875" pos="0 -0.0220203 0.03242" type="box" contype="0" conaffinity="0" group="1" rgba="0.9 0.9 0.9 1"/>
                                  <geom name="gripper0_right_right_fingertip_collision" size="0.011 0.003175 0.01875" pos="0 -0.0220203 0.03242" type="box" solref="0.01 0.25" rgba="0 0 0.5 1"/>
                                  <geom name="gripper0_right_right_fingerpad_collision" size="0.01 0.001 0.01675" pos="0 -0.0245203 0.03242" type="box" rgba="0 0 0.5 1"/>
                                </body>
                              </body>
                              <body name="gripper0_right_right_inner_knuckle" pos="0 0.0127 0.06142">
                                <inertial pos="0.000123012 0.0507851 0.00103969" quat="0.497203 0.502496 -0.507943 0.492221" mass="0.0271177" diaginertia="2.83809e-05 2.61936e-05 2.81319e-06"/>
                                <joint name="gripper0_right_right_inner_knuckle_joint" pos="0 0 0" axis="1 0 0" limited="true" range="0 0.8757"/>
                                <geom name="gripper0_right_right_inner_knuckle_visual" type="mesh" contype="0" conaffinity="0" group="1" rgba="0.1 0.1 0.1 1" mesh="gripper0_right_robotiq_arg2f_85_inner_knuckle_vis"/>
                                <geom name="gripper0_right_right_inner_knuckle_collision" type="mesh" rgba="0 0 0.5 1" mesh="gripper0_right_robotiq_arg2f_85_inner_knuckle"/>
                              </body>
                            </body>
                          </body>
                        </body>
                      </body>
                    </body>
                  </body>
                </body>
              </body>
            </body>
          </body>
        </body>
      </body>
    </body>
    <body name="peg_main">
      <joint name="peg_joint0" type="free" damping="0.0005"/>
      <geom name="peg_g0" quat="0.499998 0.5 0.5 0.500002" type="mesh" conaffinity="0" condim="4" group="1" friction="5 0.3 0.1" solref="0.002" solimp="0.95 0.95 0.01" density="100" mesh="peg_mesh"/>
      <geom name="peg_g1" quat="0.499998 0.5 0.5 0.500002" type="mesh" density="100" rgba="0.5 0 0 1" mesh="peg_mesh"/>
      <geom name="peg_g1_visual" quat="0.499998 0.5 0.5 0.500002" type="mesh" contype="0" conaffinity="0" group="1" mass="0" mesh="peg_mesh"/>
      <site name="peg_default_site" pos="0 0 0" size="0.002" rgba="1 0 0 0"/>
    </body>
    <body name="slot_main">
      <joint name="slot_joint0" type="free" damping="0.0005"/>
      <geom name="slot_g0" type="mesh" condim="4" friction="0.95 0.3 0.1" solref="0.001" solimp="0.998 0.998" density="50" rgba="0.5 0 0 1" mesh="slot_cuboid_col_0"/>
      <geom name="slot_g1" type="mesh" condim="4" friction="0.95 0.3 0.1" solref="0.001" solimp="0.998 0.998" rgba="0.5 0 0 1" mesh="slot_cuboid_col_1"/>
      <geom name="slot_g2" type="mesh" condim="4" friction="0.95 0.3 0.1" solref="0.001" solimp="0.998 0.998" rgba="0.5 0 0 1" mesh="slot_cuboid_col_2"/>
      <geom name="slot_g3" type="mesh" condim="4" friction="0.95 0.3 0.1" solref="0.001" solimp="0.998 0.998" rgba="0.5 0 0 1" mesh="slot_cuboid_col_3"/>
      <geom name="slot_g4" type="mesh" condim="4" friction="0.95 0.3 0.1" solref="0.001" solimp="0.998 0.998" rgba="0.5 0 0 1" mesh="slot_cuboid_col_4"/>
      <geom name="slot_g5" type="mesh" condim="4" friction="0.95 0.3 0.1" solref="0.001" solimp="0.998 0.998" rgba="0.5 0 0 1" mesh="slot_cuboid_col_5"/>
      <geom name="slot_g6" type="mesh" condim="4" friction="0.95 0.3 0.1" solref="0.001" solimp="0.998 0.998" rgba="0.5 0 0 1" mesh="slot_cuboid_col_6"/>
      <geom name="slot_g7" type="mesh" condim="4" friction="0.95 0.3 0.1" solref="0.001" solimp="0.998 0.998" rgba="0.5 0 0 1" mesh="slot_cuboid_col_7"/>
      <geom name="slot_g8" type="mesh" condim="4" friction="0.95 0.3 0.1" solref="0.001" solimp="0.998 0.998" rgba="0.5 0 0 1" mesh="slot_cuboid_col_8"/>
      <geom name="slot_g9" type="mesh" condim="4" friction="0.95 0.3 0.1" solref="0.001" solimp="0.998 0.998" rgba="0.5 0 0 1" mesh="slot_cuboid_col_9"/>
      <geom name="slot_g10" type="mesh" condim="4" friction="0.95 0.3 0.1" solref="0.001" solimp="0.998 0.998" rgba="0.5 0 0 1" mesh="slot_cuboid_col_10"/>
      <geom name="slot_g11" type="mesh" condim="4" friction="0.95 0.3 0.1" solref="0.001" solimp="0.998 0.998" rgba="0.5 0 0 1" mesh="slot_cuboid_col_11"/>
      <geom name="slot_g12" type="mesh" contype="0" conaffinity="0" rgba="0.5 0 0 1" mesh="slot_cuboid_mesh"/>
      <geom name="slot_g0_visual" type="mesh" contype="0" conaffinity="0" condim="4" group="1" friction="0.95 0.3 0.1" solref="0.001" solimp="0.998 0.998" mass="0" mesh="slot_cuboid_col_0"/>
      <geom name="slot_g1_visual" type="mesh" contype="0" conaffinity="0" condim="4" group="1" friction="0.95 0.3 0.1" solref="0.001" solimp="0.998 0.998" mass="0" mesh="slot_cuboid_col_1"/>
      <geom name="slot_g2_visual" type="mesh" contype="0" conaffinity="0" condim="4" group="1" friction="0.95 0.3 0.1" solref="0.001" solimp="0.998 0.998" mass="0" mesh="slot_cuboid_col_2"/>
      <geom name="slot_g3_visual" type="mesh" contype="0" conaffinity="0" condim="4" group="1" friction="0.95 0.3 0.1" solref="0.001" solimp="0.998 0.998" mass="0" mesh="slot_cuboid_col_3"/>
      <geom name="slot_g4_visual" type="mesh" contype="0" conaffinity="0" condim="4" group="1" friction="0.95 0.3 0.1" solref="0.001" solimp="0.998 0.998" mass="0" mesh="slot_cuboid_col_4"/>
      <geom name="slot_g5_visual" type="mesh" contype="0" conaffinity="0" condim="4" group="1" friction="0.95 0.3 0.1" solref="0.001" solimp="0.998 0.998" mass="0" mesh="slot_cuboid_col_5"/>
      <geom name="slot_g6_visual" type="mesh" contype="0" conaffinity="0" condim="4" group="1" friction="0.95 0.3 0.1" solref="0.001" solimp="0.998 0.998" mass="0" mesh="slot_cuboid_col_6"/>
      <geom name="slot_g7_visual" type="mesh" contype="0" conaffinity="0" condim="4" group="1" friction="0.95 0.3 0.1" solref="0.001" solimp="0.998 0.998" mass="0" mesh="slot_cuboid_col_7"/>
      <geom name="slot_g8_visual" type="mesh" contype="0" conaffinity="0" condim="4" group="1" friction="0.95 0.3 0.1" solref="0.001" solimp="0.998 0.998" mass="0" mesh="slot_cuboid_col_8"/>
      <geom name="slot_g9_visual" type="mesh" contype="0" conaffinity="0" condim="4" group="1" friction="0.95 0.3 0.1" solref="0.001" solimp="0.998 0.998" mass="0" mesh="slot_cuboid_col_9"/>
      <geom name="slot_g10_visual" type="mesh" contype="0" conaffinity="0" condim="4" group="1" friction="0.95 0.3 0.1" solref="0.001" solimp="0.998 0.998" mass="0" mesh="slot_cuboid_col_10"/>
      <geom name="slot_g11_visual" type="mesh" contype="0" conaffinity="0" condim="4" group="1" friction="0.95 0.3 0.1" solref="0.001" solimp="0.998 0.998" mass="0" mesh="slot_cuboid_col_11"/>
      <geom name="slot_g12_visual" type="mesh" contype="0" conaffinity="0" group="1" mass="0" rgba="0.8 0.8 0.8 1" mesh="slot_cuboid_mesh"/>
      <site name="slot_default_site" pos="0 0 0" size="0.002" rgba="1 0 0 0"/>
    </body>
  </worldbody>

  <tendon>
    <fixed name="gripper0_right_finger2_12_cpl" limited="true" range="-1 1" stiffness="0.4" springlength="0.001">
      <joint joint="gripper0_right_finger_joint" coef="1"/>
      <joint joint="gripper0_right_left_inner_finger_joint" coef="-3"/>
      <joint joint="gripper0_right_left_inner_knuckle_joint" coef="1"/>
    </fixed>
    <fixed name="gripper0_right_finger1_12_cpl" limited="true" range="-1 1" stiffness="0.4" springlength="0.001">
      <joint joint="gripper0_right_right_outer_knuckle_joint" coef="1"/>
      <joint joint="gripper0_right_right_inner_finger_joint" coef="-3"/>
      <joint joint="gripper0_right_right_inner_knuckle_joint" coef="1"/>
    </fixed>
  </tendon>

  <actuator>
    <general name="robot0_torq_j1" joint="robot0_joint1" ctrllimited="true" ctrlrange="-80 80"/>
    <general name="robot0_torq_j2" joint="robot0_joint2" ctrllimited="true" ctrlrange="-80 80"/>
    <general name="robot0_torq_j3" joint="robot0_joint3" ctrllimited="true" ctrlrange="-80 80"/>
    <general name="robot0_torq_j4" joint="robot0_joint4" ctrllimited="true" ctrlrange="-80 80"/>
    <general name="robot0_torq_j5" joint="robot0_joint5" ctrllimited="true" ctrlrange="-80 80"/>
    <general name="robot0_torq_j6" joint="robot0_joint6" ctrllimited="true" ctrlrange="-12 12"/>
    <general name="robot0_torq_j7" joint="robot0_joint7" ctrllimited="true" ctrlrange="-12 12"/>
    <general name="gripper0_right_finger_1" joint="gripper0_right_finger_joint" ctrllimited="true" ctrlrange="0 0.8" biastype="affine" gainprm="20" biasprm="0 -20"/>
    <general name="gripper0_right_finger_2" joint="gripper0_right_right_outer_knuckle_joint" ctrllimited="true" ctrlrange="0 0.8" biastype="affine" gainprm="20" biasprm="0 -20"/>
  </actuator>

  <sensor>
    <force site="gripper0_right_ft_frame" name="gripper0_right_force_ee"/>
    <torque site="gripper0_right_ft_frame" name="gripper0_right_torque_ee"/>
  </sensor>
</mujoco>
